Workbook

Sheet PRODUCT_SUMMARY
A1: Years | B1: DATE | C1: Product Code | D1: Product Name | E1: Per Piece USD | F1: Per Piece INR | G1: TOTAL VALUE INR (FOB) | H1: Total Duty Paid_INR | I1: Duty % | J1: Grand Total (FOB + Duty) | K1: Sum of Qty in Pieces | L1: Sum of Qty in Kgs
A2: 2017 | C2: AISI430 | D2: AISI430 | F2: 10.520779 | G2: 1052919.6 | H2: 180028.2 | I2: 0.17098001 | J2: 1232947.8 | K2: 2 | L2: 0
A3: 2017 | C3: FAMILY | D3: FAMILY | F3: 1274.0893 | G3: 1496554 | H3: 352228.9 | I3: 0.23535997 | J3: 1848782.9 | K3: 10291 | L3: 0
A4: 2017 | C4: KWB-600F | D4: KWB-600F | E4: 1.1 | F4: 187.93972 | G4: 15042837 | H4: 3314417.3 | I4: 0.22033193 | J4: 18357254 | K4: 50400 | L4: 0
A5: 2017 | C5: KWP-1000B | D5: KWP-1000B | F5: 110.89896 | G5: 5336256.4 | H5: 1255941.3 | I5: 0.23536 | J5: 6592197.7 | K5: 0 | L5: 0
A6: 2017 | C6: KWP-1000B-SS | D6: KWP-1000B-SS | F6: 111.28034 | G6: 667682.06 | H6: 114160.3 | I6: 0.17098003 | J6: 781842.36 | K6: 0 | L6: 0
A7: 2017 | C7: KWP-600B | D7: KWP-600B | F7: 90.856981 | G7: 1640794.5 | H7: 386177.3 | I7: 0.23535995 | J7: 2026971.8 | K7: 0 | L7: 0
A8: 2017 | C8: KWP-600B-SS | D8: KWP-600B-SS | F8: 91.16944 | G8: 182338.88 | H8: 31176.4 | I8: 0.17098054 | J8: 213515.28 | K8: 0 | L8: 0
A9: 2017 | C9: MULTI | D9: MULTI | F9: 617.96434 | G9: 5636403 | H9: 1326583.9 | I9: 0.23536002 | J9: 6962986.9 | K9: 0 | L9: 0
A10: 2017 | C10: OIL | D10: OIL | F10: 105.05123 | G10: 3021267.7 | H10: 516576.5 | I10: 0.17098005 | J10: 3537844.2 | K10: 4295 | L10: 0
A11: 2017 | C11: STAINESS | D11: STAINESS | F11: 111.67348 | G11: 974505.99 | H11: 229359.6 | I11: 0.23535987 | J11: 1203865.6 | K11: 171 | L11: 0
A12: 2017 | C12: STAINLESS | D12: STAINLESS | F12: 76.793011 | G12: 52907530 | H12: 10270798 | I12: 0.19412734 | J12: 63178328 | K12: 15727 | L12: 0
A13: 2017 | C13: STEEL | D13: STEEL | F13: 44.435759 | G13: 69515786 | H13: 14591660 | I13: 0.20990426 | J13: 84107446 | K13: 73594 | L13: 0
A14: 2017 | C14: TEA | D14: TEA | F14: 63.64661 | G14: 768366.94 | H14: 180842.8 | I14: 0.23535994 | J14: 949209.74 | K14: 166 | L14: 0
A15: 2018 | C15: 03-0271 | D15: 03-0271 | F15: 140.10421 | G15: 1499255.1 | H15: 364618.9 | I15: 0.24320003 | J15: 1863874 | K15: 1800 | L15: 0
A16: 2018 | C16: 03-027I | D16: 03-027I | F16: 834.13119 | G16: 4504356.7 | H16: 1095459.6 | I16: 0.24320001 | J16: 5599816.3 | K16: 5400 | L16: 0
... A37: 2019 | C37: KWB-600F | D37: KWB-600F | F37: 345.82861 | G37: 11469684 | H37: 3023087.3 | I37: 0.26357198 | J37: 14492771 | K37: 100800 | L37: 0
A38: 2019 | C38: KWP-1000B | D38: KWP-1000B | E38: 1.52 | F38: 432.26889 | G38: 2917815 | H38: 709612.7 | I38: 0.24320003 | J38: 3627427.7 | K38: 27000 | L38: 0
A39: 2019 | C39: KWP-1000B- | D39: KWP-1000B- | E39: 1.53 | F39: 422.89142 | G39: 1189170.7 | H39: 289206.3 | I39: 0.24319999 | J39: 1478377 | K39: 11100 | L39: 0
A40: 2019 | C40: KWP-1000B-SS | D40: KWP-1000B-SS | F40: 111.2741 | G40: 2470285 | H40: 600773.4 | I40: 0.24320003 | J40: 3071058.4 | K40: 0 | L40: 0
A41: 2019 | C41: KWP-600B | D41: KWP-600B | E41: 1.26 | F41: 496.89038 | G41: 3484592.8 | H41: 847453 | I41: 0.24320001 | J41: 4332045.8 | K41: 38960 | L41: 0
A42: 2019 | C42: KWP-600B- | D42: KWP-600B- | E42: 1.26 | F42: 497.87709 | G42: 599941.89 | H42: 145905.9 | I42: 0.24320005 | J42: 745847.79 | K42: 6800 | L42: 0
A43: 2019 | C43: KWP-600B-SS | D43: KWP-600B-SS | F43: 91.637494 | G43: 1246269.9 | H43: 303092.9 | I43: 0.24320004 | J43: 1549362.8 | K43: 0 | L43: 0
A44: 2019 | C44: KWS-750C | D44: KWS-750C | F44: 71.99757 | G44: 1381489.4 | H44: 335978.2 | I44: 0.24319999 | J44: 1717467.6 | K44: 0 | L44: 0
A45: 2019 | C45: KWS-750D- | D45: KWS-750D- | F45: 79.197326 | G45: 1542447.1 | H45: 375123.2 | I45: 0.24320004 | J45: 1917570.3 | K45: 0 | L45: 0
A46: 2019 | C46: OIL | D46: OIL | F46: 443.38687 | G46: 5745959.4 | H46: 1397417.4 | I46: 0.24320001 | J46: 7143376.8 | K46: 51840 | L46: 0
A47: 2019 | C47: RYX-02-020 | D47: RYX-02-020 | F47: 312.74015 | G47: 14979173 | H47: 3642934.7 | I47: 0.2432 | J47: 18622107 | K47: 1232 | L47: 0
A48: 2019 | C48: RYX-02-021A | D48: RYX-02-021A | F48: 211.51741 | G48: 37042206 | H48: 9008664.9 | I48: 0.24320001 | J48: 46050871 | K48: 3888 | L48: 0
A49: 2019 | C49: SCOURER | D49: SCOURER | F49: 250.07735 | G49: 1600745.1 | H49: 495910.9 | I49: 0.30980004 | J49: 2096656 | K49: 106800 | L49: 0
A50: 2019 | C50: SCRUBBER | D50: SCRUBBER | F50: 208.39187 | G50: 1612953.1 | H50: 499692.8 | I50: 0.30979996 | J50: 2112645.9 | K50: 3 | L50: 0
A51: 2019 | C51: SM1168 | D51: SM1168 | E51: 1.22 | F51: 277.10698 | G51: 2656771.2 | H51: 646126.8 | I51: 0.24320001 | J51: 3302898 | K51: 28200 | L51: 0
A52: 2019 | C52: STAINLESS | D52: STAINLESS | F52: 391.31875 | G52: 1.0148424e+08 | H52: 24680968 | I52: 0.24320001 | J52: 1.2616521e+08 | K52: 602622 | L52: 0
A53: 2019 | C53: STEEL | D53: STEEL | E53: 0.17 | F53: 395.31046 | G53: 2.0325064e+08 | H53: 50519864 | I53: 0.24855944 | J53: 2.537705e+08 | K53: 3284295 | L53: 0
A54: 2020 | C54: 03-027I | D54: 03-027I | F54: 156.47907 | G54: 11480838 | H54: 4206578.9 | I54: 0.36639998 | J54: 15687417 | K54: 12768 | L54: 0
A55: 2020 | C55: 2628 | D55: 2628 | E55: 0.445 | F55: 1033.3315 | G55: 3396229.9 | H55: 1244378.7 | I55: 0.36640002 | J55: 4640608.6 | K55: 96984 | L55: 0
A56: 2020 | C56: HOUSEHOLD | D56: HOUSEHOLD | E56: 0.445 | F56: 1005.6147 | G56: 6773664.9 | H56: 2197338.3 | I56: 0.3243943 | J56: 8971003.2 | K56: 36225 | L56: 0
A57: 2020 | C57: KW-830 | D57: KW-830 | E57: 0.98 | F57: 384.18896 | G57: 5240958.9 | H57: 1607565.8 | I57: 0.30673124 | J57: 6848524.7 | K57: 70200 | L57: 0
A58: 2020 | C58: KWB-600F | D58: KWB-600F | E58: 0.99 | F58: 477.48242 | G58: 3767498.4 | H58: 1380411.3 | I58: 0.36639997 | J58: 5147909.7 | K58: 49536 | L58: 0
A59: 2020 | C59: KWP-1000B | D59: KWP-1000B | E59: 1.438 | F59: 461.24285 | G59: 11982707 | H59: 4036732.6 | I59: 0.33687986 | J59: 16019439 | K59: 108036 | L59: 0
A60: 2020 | C60: KWP-600P | D60: KWP-600P | E60: 1.2 | F60: 546.8889 | G60: 3709547.4 | H60: 1359178.1 | I60: 0.36639998 | J60: 5068725.5 | K60: 38760 | L60: 0
...

Sheet OUTPUT
A1: Siddharth Associates — Data Analyst Assignment Output
A3: Summary | B3: Total Input Rows | C3: 2079
B4: Years Covered | C4: =IFERROR(0,0) -> 0
B5: Total Value (INR) | C5: =IFERROR(0,0) -> 0
B6: Total Duty Paid (INR) | C6: =IFERROR(0,0) -> 0
B7: Grand Total (INR) | C7: =IFERROR(0,0) -> 0
A10: YEAR | B10: TOTAL_VALUE_INR | C10: DUTY_PAID_INR | D10: GRAND_TOTAL_INR | E10: YOY_GROWTH_PCT
A11: 2017 | B11: =SUMIFS(CLEANED_DATA!Q2:'CLEANED_DATA'!Q2080,CLEANED_DATA!AB2:'CLEANED_DATA'!AB2080,A2) -> 0 | C11: =SUMIFS(CLEANED_DATA!T2:'CLEANED_DATA'!T2080,CLEANED_DATA!AB2:'CLEANED_DATA'!AB2080,A2) -> 0 | D11: =SUMIFS(CLEANED_DATA!AC2:'CLEANED_DATA'!AC2080,CLEANED_DATA!AB2:'CLEANED_DATA'!AB2080,A2) -> 0
A12: 2018 | B12: =SUMIFS(CLEANED_DATA!Q2:'CLEANED_DATA'!Q2080,CLEANED_DATA!AB2:'CLEANED_DATA'!AB2080,A3) -> 0 | C12: =SUMIFS(CLEANED_DATA!T2:'CLEANED_DATA'!T2080,CLEANED_DATA!AB2:'CLEANED_DATA'!AB2080,A3) -> 0 | D12: =SUMIFS(CLEANED_DATA!AC2:'CLEANED_DATA'!AC2080,CLEANED_DATA!AB2:'CLEANED_DATA'!AB2080,A3) -> 0 | E12: =IF(B2=0,"",(B3-B2)/B2)
A13: 2019 | B13: =SUMIFS(CLEANED_DATA!Q2:'CLEANED_DATA'!Q2080,CLEANED_DATA!AB2:'CLEANED_DATA'!AB2080,A4) -> 0 | C13: =SUMIFS(CLEANED_DATA!T2:'CLEANED_DATA'!T2080,CLEANED_DATA!AB2:'CLEANED_DATA'!AB2080,A4) -> 0 | D13: =SUMIFS(CLEANED_DATA!AC2:'CLEANED_DATA'!AC2080,CLEANED_DATA!AB2:'CLEANED_DATA'!AB2080,A4) -> 0 | E13: =IF(B3=0,"",(B4-B3)/B3) -> #VALUE!
A14: 2020 | B14: =SUMIFS(CLEANED_DATA!Q2:'CLEANED_DATA'!Q2080,CLEANED_DATA!AB2:'CLEANED_DATA'!AB2080,A5) -> 0 | C14: =SUMIFS(CLEANED_DATA!T2:'CLEANED_DATA'!T2080,CLEANED_DATA!AB2:'CLEANED_DATA'!AB2080,A5) -> 0 | D14: =SUMIFS(CLEANED_DATA!AC2:'CLEANED_DATA'!AC2080,CLEANED_DATA!AB2:'CLEANED_DATA'!AB2080,A5) -> 0 | E14: =IF(B4=0,"",(B5-B4)/B4) -> #VALUE!
A15: 2021 | B15: =SUMIFS(CLEANED_DATA!Q2:'CLEANED_DATA'!Q2080,CLEANED_DATA!AB2:'CLEANED_DATA'!AB2080,A6) -> 0 | C15: =SUMIFS(CLEANED_DATA!T2:'CLEANED_DATA'!T2080,CLEANED_DATA!AB2:'CLEANED_DATA'!AB2080,A6) -> 0 | D15: =SUMIFS(CLEANED_DATA!AC2:'CLEANED_DATA'!AC2080,CLEANED_DATA!AB2:'CLEANED_DATA'!AB2080,A6) -> 0 | E15: =IF(B5=0,"",(B6-B5)/B5) -> #VALUE!
A16: 2022 | B16: =SUMIFS(CLEANED_DATA!Q2:'CLEANED_DATA'!Q2080,CLEANED_DATA!AB2:'CLEANED_DATA'!AB2080,A7) -> 0 | C16: =SUMIFS(CLEANED_DATA!T2:'CLEANED_DATA'!T2080,CLEANED_DATA!AB2:'CLEANED_DATA'!AB2080,A7) -> 0 | D16: =SUMIFS(CLEANED_DATA!AC2:'CLEANED_DATA'!AC2080,CLEANED_DATA!AB2:'CLEANED_DATA'!AB2080,A7) -> 0 | E16: =IF(B6=0,"",(B7-B6)/B6) -> #VALUE!
A20: HSN | B20: HSN_DESCRIPTION | C20: MAIN_CATEGORY | D20: SUB_CATEGORY | E20: TOTAL_VALUE_INR | F20: DUTY_PAID_INR | G20: GRAND_TOTAL_INR | H20: %_CONTRIBUTION
A21: 73231000 | B21: Stainless steel scouring pads and similar | C21: Cleaning Supplies | D21: Scrubber | E21: =SUMIFS(CLEANED_DATA!Q2:'CLEANED_DATA'!Q2080,CLEANED_DATA!D2:'CLEANED_DATA'!D2080,A2) -> 0 | F21: =SUMIFS(CLEANED_DATA!T2:'CLEANED_DATA'!T2080,CLEANED_DATA!D2:'CLEANED_DATA'!D2080,A2) -> 0 | G21: =SUMIFS(CLEANED_DATA!AC2:'CLEANED_DATA'!AC2080,CLEANED_DATA!D2:'CLEANED_DATA'!D2080,A2) -> 0 | H21: =IF($E$6=0,0,E2/$E$6) -> 0
A22: 73239390 | B22: Table, kitchen or other household articles of stainless steel | C22: Stainless Steel Household Articles | D22: Kitchenware | E22: =SUMIFS(CLEANED_DATA!Q2:'CLEANED_DATA'!Q2080,CLEANED_DATA!D2:'CLEANED_DATA'!D2080,A3) -> 0 | F22: =SUMIFS(CLEANED_DATA!T2:'CLEANED_DATA'!T2080,CLEANED_DATA!D2:'CLEANED_DATA'!D2080,A3) -> 0 | G22: =SUMIFS(CLEANED_DATA!AC2:'CLEANED_DATA'!AC2080,CLEANED_DATA!D2:'CLEANED_DATA'!D2080,A3) -> 0 | H22: =IF($E$6=0,0,E3/$E$6) -> 0
A23: 73239990 | B23: Table, kitchen or other household articles of iron or steel | C23: Steel Household Articles | D23: Household Article | E23: =SUMIFS(CLEANED_DATA!Q2:'CLEANED_DATA'!Q2080,CLEANED_DATA!D2:'CLEANED_DATA'!D2080,A4) -> 0 | F23: =SUMIFS(CLEANED_DATA!T2:'CLEANED_DATA'!T2080,CLEANED_DATA!D2:'CLEANED_DATA'!D2080,A4) -> 0 | G23: =SUMIFS(CLEANED_DATA!AC2:'CLEANED_DATA'!AC2080,CLEANED_DATA!D2:'CLEANED_DATA'!D2080,A4) -> 0 | H23: =IF($E$6=0,0,E4/$E$6) -> 0
D25: Overall Grand Total | E25: =SUM(E2:E4) -> 0
A40: Notes: All calculations are formula-driven. See CLEANED_DATA, YEAR_SUMMARY, HSN_SUMMARY_V2 for details.

Sheet INPUT_RAW
A1: PORT CODE | B1: DATE | C1: IEC | D1: HS CODE | E1: GOODS DESCRIPTION | F1: Master category | G1: Model Name | H1: Model Number | I1: Capacity | J1: Qty | K1: Unit of measure | L1: Price | M1: Unit of measure.1 | N1: QUANTITY | O1: UNIT | P1: UNIT PRICE_INR | Q1: TOTAL VALUE_INR | R1: UNIT PRICE_USD | S1: TOTAL VALUE_USD | T1: DUTY PAID_INR
A2: INNSA1 | B2: 2025-10-28 | C2: 301049751 | D2: 73239990 | E2: TH5170 STEEL CUTLERY HOLDER (QTY:600 PCS/USD 2.03 PER PCS) TH5170 STEEL CUTLERY HOLDER (QTY:600 PCS/USD 2.03 PER PCS) | N2: 290 | O2: KGS | P2: 401.72531 | Q2: 116500.34 | R2: 4.5290339 | S2: 1313.4198 | T2: 32736.6
A3: INNSA1 | B3: 2025-10-28 | C3: 301049751 | D3: 73231000 | E3: 8001-2 STEEL SCRUBBER 2PCS SET (QTY: 336000 SETS/USD 0.139 PER SETS)8001-2 STEEL SCRUBBER 2PCS SET (QTY: 336000 SETS/USD 0.139 P | N3: 9800 | O3: KGS | P3: 440.60222 | Q3: 4317901.7 | R3: 4.9673305 | S3: 48679.839 | T3: 1898149.5
A4: INNSA1 | B4: 2025-10-23 | C4: 301049751 | D4: 73239990 | E4: MILD STEEL MULTI FUNCTION CLOTH STAND (RYX-02-020) (QTY: 1,232 PCS/CNY:101 PER PCS)MILD STEEL MULTI FUNCTION CLOTH STAND (RYX-02-020) (QTY: 1,2 | N4: 4004 | O4: KGS | P4: 408.89366 | Q4: 1637210.2 | R4: 4.6098496 | S4: 18457.838 | T4: 460056
A5: INNSA1 | B5: 2025-10-13 | C5: 301049751 | D5: 73239990 | E5: SB-12 STEEL TEA STRAINER BIG (QTY 6336 PCS/USD 0.973 PER PCS)SB-12 STEEL TEA STRAINER BIG (QTY 6336 PCS/USD 0.973 PER PCS | N5: 1548.8 | O5: KGS | P5: 378.45784 | Q5: 586155.51 | R5: 4.219151 | S5: 6534.6211 | T5: 164709.7
A6: INNSA1 | B6: 2025-10-13 | C6: 301049751 | D6: 73239990 | E6: SB-12 STEEL TEA STRAINER BIG (QTY 43038 PCS/USD 0.9718 PER PCS)SB-12 STEEL TEA STRAINER BIG (QTY 43038 PCS/USD 0.9718 PER P | N6: 10042.2 | O6: KGS | P6: 399.73967 | Q6: 4014265.8 | R6: 4.4564066 | S6: 44752.127 | T6: 1128008.7
A7: INNSA1 | B7: 2025-10-08 | C7: 301049751 | D7: 73239990 | E7: STEEL HANGER WITH HOOK (SL-89) (QTY:70056 PCS/CNY:7.45 PER PCS)STEEL HANGER WITH HOOK (SL-89) (QTY:70056 PCS/:7.45 | N7: 15568 | O7: KGS | P7: 432.15818 | Q7: 6727838.5 | R7: 4.8178169 | S7: 75003.774 | T7: 1890522.7
A8: INNSA1 | B8: 2025-10-06 | C8: 301049751 | D8: 73239990 | E8: STEEL HANGER 10PCS SET (AM-969) (QTY: 480 SET/USD 0.819 PERSET)STEEL HANGER 10PCS SET (AM-969) (QTY: 480 SET/USD 0.819 PER | N8: 380 | O8: KGS | P8: 100.44208 | Q8: 38167.99 | R8: 1.1197556 | S8: 425.50713 | T8: 10725.3
A9: INNSA1 | B9: 2025-10-01 | C9: 301049751 | D9: 73239990 | E9: AM-967 STEEL FRUIT BASKET (QTY 400 PCS/USD 1.031 PER PCS) AM-967 STEEL FRUIT BASKET (QTY 400 PCS/USD 1.031 PER PCS) | N9: 460 | O9: KGS | P9: 85.377826 | Q9: 39273.8 | R9: 0.96092095 | S9: 442.02364 | T9: 11036
A10: INNSA1 | B10: 2025-10-01 | C10: 301049751 | D10: 73239990 | E10: AM-966 STEEL FRUIT BASKET (QTY 400 PCS/USD 1.017 PER PCS) AM-966 STEEL FRUIT BASKET (QTY 400 PCS/USD 1.017 PER PCS) | N10: 310 | O10: KGS | P10: 124.96932 | Q10: 38740.49 | R10: 1.4065202 | S10: 436.02127 | T10: 10886.1
A11: INNSA1 | B11: 2025-10-01 | C11: 301049751 | D11: 73239990 | E11: AM-965 STEEL SPOON & FORK HOLDER (QTY 480 PCS/USD 0.734 PERPCS)AM-965 STEEL SPOON & FORK HOLDER (QTY 480 PCS/USD 0.734 PER | N11: 168 | O11: KGS | P11: 199.71571 | Q11: 33552.24 | R11: 2.2477852 | S11: 377.62791 | T11: 9428.1
A12: INNSA1 | B12: 2025-10-01 | C12: 301049751 | D12: 73231000 | E12: 8001-2 STEEL SCRUBBER 2 PCS SET (QTY 336000 SETS/USD 0.139 PER SETS)8001-2 STEEL SCRUBBER 2 PCS SET (QTY 336000 SETS/USD 0.139 P | N12: 9800 | O12: KGS | P12: 456.12539 | Q12: 4470028.8 | R12: 5.1336566 | S12: 50309.835 | T12: 1965024.7
A13: INNSA1 | B13: 2025-09-27 | C13: 301049751 | D13: 73231000 | E13: OKS-4156 STEEL SCRUBBER 6PCS SET (QTY: 93360 PCS /USD 0.228PER PCS)OKS-4156 STEEL SCRUBBER 6PCS SET (QTY: 93360 PCS /USD 0.228 | N13: 7496.03 | O13: KGS | P13: 263.57138 | Q13: 1975739 | R13: 2.9664758 | S13: 22236.792 | T13: 868534.9
... A2080: INNSA1 | B2080: 2017-01-13 | C2080: 301049751 | D2080: 73239990 | E2080: STAINLESS STEEL SPORTS BOTTLE 750ML S-308-C6-NP-20(TOTAL NET WT.284.83 KGS) | N2080: 1656 | O2080: PCS | P2080: 79.149233 | Q2080: 131071.13 | R2080: 1.1504249 | S2080: 1905.1036 | T2080: 22410.6

Sheet CLEANED_DATA
A1: PORT CODE | B1: DATE | C1: IEC | D1: HS CODE | E1: GOODS DESCRIPTION | F1: Master category | G1: Model Name | H1: Model Number | I1: Capacity | J1: Qty | K1: Unit of measure | L1: Price | M1: Unit of measure.1 | N1: QUANTITY | O1: UNIT | P1: UNIT PRICE_INR | Q1: TOTAL VALUE_INR | R1: UNIT PRICE_USD | S1: TOTAL VALUE_USD | T1: DUTY PAID_INR | U1: PARSED_QTY | V1: PARSED_UNIT_PRICE_USD | W1: PARSED_MODEL | X1: PARSED_SUBKEY | Y1: HSN_DESCRIPTION | Z1: MAIN_CATEGORY | AA1: SUB_CATEGORY | AB1: YEAR | AC1: GRAND_TOTAL_INR | AD1: DUTY_PCT
A2: INNSA1 | B2: 2025-10-28 | C2: 301049751 | D2: 73239990 | E2: TH5170 STEEL CUTLERY HOLDER (QTY:600 PCS/USD 2.03 PER PCS) TH5170 STEEL CUTLERY HOLDER (QTY:600 PCS/USD 2.03 PER PCS) | N2: 290 | O2: KGS | P2: 401.72531 | Q2: 116500.34 | R2: 4.5290339 | S2: 1313.4198 | T2: 32736.6 | U2: 600 | V2: 2.03 | W2: TH5170 | X2: Holder | Y2: Table, kitchen or other household articles of iron or steel | Z2: Steel Household Articles | AA2: Holder | AB2: =IF(INPUT_RAW!B2="","",YEAR(INPUT_RAW!B2)) -> 2025 | AC2: =IF(OR(INPUT_RAW!Q2="",INPUT_RAW!T2=""),"",INPUT_RAW!Q2+INPUT_RAW!T2) -> 149236.94 | AD2: =IF(INPUT_RAW!Q2="","",IF(INPUT_RAW!Q2=0,0,INPUT_RAW!T2/INPUT_RAW!Q2)) -> 0.28100004
A3: INNSA1 | B3: 2025-10-28 | C3: 301049751 | D3: 73231000 | E3: 8001-2 STEEL SCRUBBER 2PCS SET (QTY: 336000 SETS/USD 0.139 PER SETS)8001-2 STEEL SCRUBBER 2PCS SET (QTY: 336000 SETS/USD 0.139 P | N3: 9800 | O3: KGS | P3: 440.60222 | Q3: 4317901.7 | R3: 4.9673305 | S3: 48679.839 | T3: 1898149.5 | U3: 336000 | V3: 0.139 | W3: 8001-2 | X3: Scrubber | Y3: Stainless steel scouring pads and similar | Z3: Cleaning Supplies | AA3: Scrubber | AB3: =IF(INPUT_RAW!B3="","",YEAR(INPUT_RAW!B3)) -> 2025 | AC3: =IF(OR(INPUT_RAW!Q3="",INPUT_RAW!T3=""),"",INPUT_RAW!Q3+INPUT_RAW!T3) -> 6216051.2 | AD3: =IF(INPUT_RAW!Q3="","",IF(INPUT_RAW!Q3=0,0,INPUT_RAW!T3/INPUT_RAW!Q3)) -> 0.43959998
A4: INNSA1 | B4: 2025-10-23 | C4: 301049751 | D4: 73239990 | E4: MILD STEEL MULTI FUNCTION CLOTH STAND (RYX-02-020) (QTY: 1,232 PCS/CNY:101 PER PCS)MILD STEEL MULTI FUNCTION CLOTH STAND (RYX-02-020) (QTY: 1,2 | N4: 4004 | O4: KGS | P4: 408.89366 | Q4: 1637210.2 | R4: 4.6098496 | S4: 18457.838 | T4: 460056 | U4: 1232 | W4: MILD | X4: Stand | Y4: Table, kitchen or other household articles of iron or steel | Z4: Steel Household Articles | AA4: Stand | AB4: =IF(INPUT_RAW!B4="","",YEAR(INPUT_RAW!B4)) -> 2025 | AC4: =IF(OR(INPUT_RAW!Q4="",INPUT_RAW!T4=""),"",INPUT_RAW!Q4+INPUT_RAW!T4) -> 2097266.2 | AD4: =IF(INPUT_RAW!Q4="","",IF(INPUT_RAW!Q4=0,0,INPUT_RAW!T4/INPUT_RAW!Q4)) -> 0.28099995
A5: INNSA1 | B5: 2025-10-13 | C5: 301049751 | D5: 73239990 | E5: SB-12 STEEL TEA STRAINER BIG (QTY 6336 PCS/USD 0.973 PER PCS)SB-12 STEEL TEA STRAINER BIG (QTY 6336 PCS/USD 0.973 PER PCS | N5: 1548.8 | O5: KGS | P5: 378.45784 | Q5: 586155.51 | R5: 4.219151 | S5: 6534.6211 | T5: 164709.7 | U5: 6336 | V5: 0.973 | W5: SB-12 | X5: Strainer | Y5: Table, kitchen or other household articles of iron or steel | Z5: Steel Household Articles | AA5: Strainer | AB5: =IF(INPUT_RAW!B5="","",YEAR(INPUT_RAW!B5)) -> 2025 | AC5: =IF(OR(INPUT_RAW!Q5="",INPUT_RAW!T5=""),"",INPUT_RAW!Q5+INPUT_RAW!T5) -> 750865.21 | AD5: =IF(INPUT_RAW!Q5="","",IF(INPUT_RAW!Q5=0,0,INPUT_RAW!T5/INPUT_RAW!Q5)) -> 0.281
A6: INNSA1 | B6: 2025-10-13 | C6: 301049751 | D6: 73239990 | E6: SB-12 STEEL TEA STRAINER BIG (QTY 43038 PCS/USD 0.9718 PER PCS)SB-12 STEEL TEA STRAINER BIG (QTY 43038 PCS/USD 0.9718 PER P | N6: 10042.2 | O6: KGS | P6: 399.73967 | Q6: 4014265.8 | R6: 4.4564066 | S6: 44752.127 | T6: 1128008.7 | U6: 43038 | V6: 0.9718 | W6: SB-12 | X6: Strainer | Y6: Table, kitchen or other household articles of iron or steel | Z6: Steel Household Articles | AA6: Strainer | AB6: =IF(INPUT_RAW!B6="","",YEAR(INPUT_RAW!B6)) -> 2025 | AC6: =IF(OR(INPUT_RAW!Q6="",INPUT_RAW!T6=""),"",INPUT_RAW!Q6+INPUT_RAW!T6) -> 5142274.5 | AD6: =IF(INPUT_RAW!Q6="","",IF(INPUT_RAW!Q6=0,0,INPUT_RAW!T6/INPUT_RAW!Q6)) -> 0.28100001
A7: INNSA1 | B7: 2025-10-08 | C7: 301049751 | D7: 73239990 | E7: STEEL HANGER WITH HOOK (SL-89) (QTY:70056 PCS/CNY:7.45 PER PCS)STEEL HANGER WITH HOOK (SL-89) (QTY:70056 PCS/:7.45 | N7: 15568 | O7: KGS | P7: 432.15818 | Q7: 6727838.5 | R7: 4.8178169 | S7: 75003.774 | T7: 1890522.7 | U7: 70056 | W7: STEEL | X7: Hanger | Y7: Table, kitchen or other household articles of iron or steel | Z7: Steel Household Articles | AA7: Hanger | AB7: =IF(INPUT_RAW!B7="","",YEAR(INPUT_RAW!B7)) -> 2025 | AC7: =IF(OR(INPUT_RAW!Q7="",INPUT_RAW!T7=""),"",INPUT_RAW!Q7+INPUT_RAW!T7) -> 8618361.2 | AD7: =IF(INPUT_RAW!Q7="","",IF(INPUT_RAW!Q7=0,0,INPUT_RAW!T7/INPUT_RAW!Q7)) -> 0.28100001
A8: INNSA1 | B8: 2025-10-06 | C8: 301049751 | D8: 73239990 | E8: STEEL HANGER 10PCS SET (AM-969) (QTY: 480 SET/USD 0.819 PERSET)STEEL HANGER 10PCS SET (AM-969) (QTY: 480 SET/USD 0.819 PER | N8: 380 | O8: KGS | P8: 100.44208 | Q8: 38167.99 | R8: 1.1197556 | S8: 425.50713 | T8: 10725.3 | U8: 480 | V8: 0.819 | W8: STEEL | X8: Hanger | Y8: Table, kitchen or other household articles of iron or steel | Z8: Steel Household Articles | AA8: Hanger | AB8: =IF(INPUT_RAW!B8="","",YEAR(INPUT_RAW!B8)) -> 2025 | AC8: =IF(OR(INPUT_RAW!Q8="",INPUT_RAW!T8=""),"",INPUT_RAW!Q8+INPUT_RAW!T8) -> 48893.29 | AD8: =IF(INPUT_RAW!Q8="","",IF(INPUT_RAW!Q8=0,0,INPUT_RAW!T8/INPUT_RAW!Q8)) -> 0.28100248
A9: INNSA1 | B9: 2025-10-01 | C9: 301049751 | D9: 73239990 | E9: AM-967 STEEL FRUIT BASKET (QTY 400 PCS/USD 1.031 PER PCS) AM-967 STEEL FRUIT BASKET (QTY 400 PCS/USD 1.031 PER PCS) | N9: 460 | O9: KGS | P9: 85.377826 | Q9: 39273.8 | R9: 0.96092095 | S9: 442.02364 | T9: 11036 | U9: 400 | V9: 1.031 | W9: AM-967 | X9: Basket | Y9: Table, kitchen or other household articles of iron or steel | Z9: Steel Household Articles | AA9: Basket | AB9: =IF(INPUT_RAW!B9="","",YEAR(INPUT_RAW!B9)) -> 2025 | AC9: =IF(OR(INPUT_RAW!Q9="",INPUT_RAW!T9=""),"",INPUT_RAW!Q9+INPUT_RAW!T9) -> 50309.8 | AD9: =IF(INPUT_RAW!Q9="","",IF(INPUT_RAW!Q9=0,0,INPUT_RAW!T9/INPUT_RAW!Q9)) -> 0.28100158
A10: INNSA1 | B10: 2025-10-01 | C10: 301049751 | D10: 73239990 | E10: AM-966 STEEL FRUIT BASKET (QTY 400 PCS/USD 1.017 PER PCS) AM-966 STEEL FRUIT BASKET (QTY 400 PCS/USD 1.017 PER PCS) | N10: 310 | O10: KGS | P10: 124.96932 | Q10: 38740.49 | R10: 1.4065202 | S10: 436.02127 | T10: 10886.1 | U10: 400 | V10: 1.017 | W10: AM-966 | X10: Basket | Y10: Table, kitchen or other household articles of iron or steel | Z10: Steel Household Articles | AA10: Basket | AB10: =IF(INPUT_RAW!B10="","",YEAR(INPUT_RAW!B10)) -> 2025 | AC10: =IF(OR(INPUT_RAW!Q10="",INPUT_RAW!T10=""),"",INPUT_RAW!Q10+INPUT_RAW!T10) -> 49626.59 | AD10: =IF(INPUT_RAW!Q10="","",IF(INPUT_RAW!Q10=0,0,INPUT_RAW!T10/INPUT_RAW!Q10)) -> 0.28100058
A11: INNSA1 | B11: 2025-10-01 | C11: 301049751 | D11: 73239990 | E11: AM-965 STEEL SPOON & FORK HOLDER (QTY 480 PCS/USD 0.734 PERPCS)AM-965 STEEL SPOON & FORK HOLDER (QTY 480 PCS/USD 0.734 PER | N11: 168 | O11: KGS | P11: 199.71571 | Q11: 33552.24 | R11: 2.2477852 | S11: 377.62791 | T11: 9428.1 | U11: 480 | V11: 0.734 | W11: AM-965 | X11: Holder | Y11: Table, kitchen or other household articles of iron or steel | Z11: Steel Household Articles | AA11: Holder | AB11: =IF(INPUT_RAW!B11="","",YEAR(INPUT_RAW!B11)) -> 2025 | AC11: =IF(OR(INPUT_RAW!Q11="",INPUT_RAW!T11=""),"",INPUT_RAW!Q11+INPUT_RAW!T11) -> 42980.34 | AD11: =IF(INPUT_RAW!Q11="","",IF(INPUT_RAW!Q11=0,0,INPUT_RAW!T11/INPUT_RAW!Q11)) -> 0.28099763
A12: INNSA1 | B12: 2025-10-01 | C12: 301049751 | D12: 73231000 | E12: 8001-2 STEEL SCRUBBER 2 PCS SET (QTY 336000 SETS/USD 0.139 PER SETS)8001-2 STEEL SCRUBBER 2 PCS SET (QTY 336000 SETS/USD 0.139 P | N12: 9800 | O12: KGS | P12: 456.12539 | Q12: 4470028.8 | R12: 5.1336566 | S12: 50309.835 | T12: 1965024.7 | U12: 336000 | V12: 0.139 | W12: 8001-2 | X12: Scrubber | Y12: Stainless steel scouring pads and similar | Z12: Cleaning Supplies | AA12: Scrubber | AB12: =IF(INPUT_RAW!B12="","",YEAR(INPUT_RAW!B12)) -> 2025 | AC12: =IF(OR(INPUT_RAW!Q12="",INPUT_RAW!T12=""),"",INPUT_RAW!Q12+INPUT_RAW!T12) -> 6435053.5 | AD12: =IF(INPUT_RAW!Q12="","",IF(INPUT_RAW!Q12=0,0,INPUT_RAW!T12/INPUT_RAW!Q12)) -> 0.43960001
A13: INNSA1 | B13: 2025-09-27 | C13: 301049751 | D13: 73231000 | E13: OKS-4156 STEEL SCRUBBER 6PCS SET (QTY: 93360 PCS /USD 0.228PER PCS)OKS-4156 STEEL SCRUBBER 6PCS SET (QTY: 93360 PCS /USD 0.228 | N13: 7496.03 | O13: KGS | P13: 263.57138 | Q13: 1975739 | R13: 2.9664758 | S13: 22236.792 | T13: 868534.9 | U13: 93360 | V13: 0.228 | W13: OKS-4156 | X13: Scrubber | Y13: Stainless steel scouring pads and similar | Z13: Cleaning Supplies | AA13: Scrubber | AB13: =IF(INPUT_RAW!B13="","",YEAR(INPUT_RAW!B13)) -> 2025 | AC13: =IF(OR(INPUT_RAW!Q13="",INPUT_RAW!T13=""),"",INPUT_RAW!Q13+INPUT_RAW!T13) -> 2844273.9 | AD13: =IF(INPUT_RAW!Q13="","",IF(INPUT_RAW!Q13=0,0,INPUT_RAW!T13/INPUT_RAW!Q13)) -> 0.43960003
A14: INNSA1 | B14: 2025-09-27 | C14: 301049751 | D14: 73231000 | E14: 8001-2 STEEL SCRUBBER 2PCS SET (QTY: 168000 SETS/USD 0.139 PER SETS)8001-2 STEEL SCRUBBER 2PCS SET (QTY: 168000 SETS/USD 0.139 P | N14: 4900 | O14: KGS | P14: 442.07294 | Q14: 2166157.4 | R14: 4.9754973 | S14: 24379.937 | T14: 952242.8 | U14: 168000 | V14: 0.139 | W14: 8001-2 | X14: Scrubber | Y14: Stainless steel scouring pads and similar | Z14: Cleaning Supplies | AA14: Scrubber | AB14: =IF(INPUT_RAW!B14="","",YEAR(INPUT_RAW!B14)) -> 2025 | AC14: =IF(OR(INPUT_RAW!Q14="",INPUT_RAW!T14=""),"",INPUT_RAW!Q14+INPUT_RAW!T14) -> 3118400.2 | AD14: =IF(INPUT_RAW!Q14="","",IF(INPUT_RAW!Q14=0,0,INPUT_RAW!T14/INPUT_RAW!Q14)) -> 0.43960001
A15: INNSA1 | B15: 2025-09-24 | C15: 301049751 | D15: 73239990 | E15: AM-321 STEEL DRAINER (QTY:28752 PCS/USD 0.7050 PER PCS) AM-321 STEEL DRAINER (QTY:28752 PCS/USD 0.7050 PER PCS) | N15: 3953.4 | O15: KGS | P15: 492.73197 | Q15: 1947966.6 | R15: 5.5456609 | S15: 21924.216 | T15: 547378.6 | U15: 28752 | V15: 0.705 | W15: AM-321 | Y15: Table, kitchen or other household articles of iron or steel | Z15: Steel Household Articles | AA15: Household Article | AB15: =IF(INPUT_RAW!B15="","",YEAR(INPUT_RAW!B15)) -> 2025 | AC15: =IF(OR(INPUT_RAW!Q15="",INPUT_RAW!T15=""),"",INPUT_RAW!Q15+INPUT_RAW!T15) -> 2495345.2 | AD15: =IF(INPUT_RAW!Q15="","",IF(INPUT_RAW!Q15=0,0,INPUT_RAW!T15/INPUT_RAW!Q15)) -> 0.281
A16: INNSA1 | B16: 2025-09-24 | C16: 301049751 | D16: 73239990 | E16: HOUSEHOLD STEEL HOOK 3PCS SET (2628) (QTY: 166608 SET/USD 0.36 PER SET)HOUSEHOLD STEEL HOOK 3PCS SET (2628) (QTY: 166608 SET/USD 0. | N16: 5646.16 | O16: KGS | P16: 971.5058 | Q16: 5485277.2 | R16: 10.934224 | S16: 61736.378 | T16: 1541362.8 | U16: 166608 | V16: 0.36 | W16: HOUSEHOLD | X16: Hook | Y16: Table, kitchen or other household articles of iron or steel | Z16: Steel Household Articles | AA16: Hook | AB16: =IF(INPUT_RAW!B16="","",YEAR(INPUT_RAW!B16)) -> 2025 | AC16: =IF(OR(INPUT_RAW!Q16="",INPUT_RAW!T16=""),"",INPUT_RAW!Q16+INPUT_RAW!T16) -> 7026640 | AD16: =IF(INPUT_RAW!Q16="","",IF(INPUT_RAW!Q16=0,0,INPUT_RAW!T16/INPUT_RAW!Q16)) -> 0.28099998
A17: INNSA1 | B17: 2025-09-24 | C17: 301049751 | D17: 73239990 | E17: NP-55 STEEL TEA STRAINER (QTY:50400 PCS/USD 0.2710 PER PCS) NP-55 STEEL TEA STRAINER (QTY:50400 PCS/USD 0.2710 PER PCS) | N17: 2310 | O17: KGS | P17: 568.21426 | Q17: 1312574.9 | R17: 6.3952083 | S17: 14772.931 | T17: 368833.6 | U17: 50400 | V17: 0.271 | W17: NP-55 | X17: Strainer | Y17: Table, kitchen or other household articles of iron or steel | Z17: Steel Household Articles | AA17: Strainer | AB17: =IF(INPUT_RAW!B17="","",YEAR(INPUT_RAW!B17)) -> 2025 | AC17: =IF(OR(INPUT_RAW!Q17="",INPUT_RAW!T17=""),"",INPUT_RAW!Q17+INPUT_RAW!T17) -> 1681408.5 | AD17: =IF(INPUT_RAW!Q17="","",IF(INPUT_RAW!Q17=0,0,INPUT_RAW!T17/INPUT_RAW!Q17)) -> 0.28100003
A18: INNSA1 | B18: 2025-09-24 | C18: 301049751 | D18: 73239990 | E18: HOUSEHOLD STEEL HOOK 3PCS SET (3888) (QTY:55,296 SET/USD:0.24 PER SET)HOUSEHOLD STEEL HOOK 3PCS SET (3888) (QTY:55,296 SET/USD:0.2 | N18: 1843.2 | O18: KGS | P18: 689.9043 | Q18: 1271631.6 | R18: 7.7648205 | S18: 14312.117 | T18: 357328.4 | U18: 55296 | V18: 0.24 | W18: HOUSEHOLD | X18: Hook | Y18: Table, kitchen or other household articles of iron or steel | Z18: Steel Household Articles | AA18: Hook | AB18: =IF(INPUT_RAW!B18="","",YEAR(INPUT_RAW!B18)) -> 2025 | AC18: =IF(OR(INPUT_RAW!Q18="",INPUT_RAW!T18=""),"",INPUT_RAW!Q18+INPUT_RAW!T18) -> 1628960 | AD18: =IF(INPUT_RAW!Q18="","",IF(INPUT_RAW!Q18=0,0,INPUT_RAW!T18/INPUT_RAW!Q18)) -> 0.28099994
A19: INNSA1 | B19: 2025-09-24 | C19: 301049751 | D19: 73239990 | E19: SB-12 STEEL TEA STRAINER BIG (QTY:1026 PCS/USD 0.9770 PER PCS)SB-12 STEEL TEA STRAINER BIG (QTY:1026 PCS/USD 0.9770 PER PC | N19: 250.8 | O19: KGS | P19: 384.09426 | Q19: 96330.84 | R19: 4.3229517 | S19: 1084.1963 | T19: 27069 | U19: 1026 | V19: 0.977 | W19: SB-12 | X19: Strainer | Y19: Table, kitchen or other household articles of iron or steel | Z19: Steel Household Articles | AA19: Strainer | AB19: =IF(INPUT_RAW!B19="","",YEAR(INPUT_RAW!B19)) -> 2025 | AC19: =IF(OR(INPUT_RAW!Q19="",INPUT_RAW!T19=""),"",INPUT_RAW!Q19+INPUT_RAW!T19) -> 123399.84 | AD19: =IF(INPUT_RAW!Q19="","",IF(INPUT_RAW!Q19=0,0,INPUT_RAW!T19/INPUT_RAW!Q19)) -> 0.28100035
A20: INNSA1 | B20: 2025-09-24 | C20: 301049751 | D20: 73239990 | E20: HOUSEHOLD STEEL HOOK 3 PCS SET (2628) (QTY:432 SET/USD:0.360PER SET)HOUSEHOLD STEEL HOOK 3 PCS SET (2628) (QTY:432 SET/USD:0.360 | N20: 14.64 | O20: KGS | P20: 987.6776 | Q20: 14459.6 | R20: 11.116236 | S20: 162.7417 | T20: 4063.1 | U20: 432 | V20: 0.36 | W20: HOUSEHOLD | X20: Hook | Y20: Table, kitchen or other household articles of iron or steel | Z20: Steel Household Articles | AA20: Hook | AB20: =IF(INPUT_RAW!B20="","",YEAR(INPUT_RAW!B20)) -> 2025 | AC20: =IF(OR(INPUT_RAW!Q20="",INPUT_RAW!T20=""),"",INPUT_RAW!Q20+INPUT_RAW!T20) -> 18522.7 | AD20: =IF(INPUT_RAW!Q20="","",IF(INPUT_RAW!Q20=0,0,INPUT_RAW!T20/INPUT_RAW!Q20)) -> 0.28099671
A21: INNSA1 | B21: 2025-09-23 | C21: 301049751 | D21: 73239990 | E21: MILD STEEL MULTI FUNCTION CLOTH STAND (RYX-02-020) (QTY: 1232 PCS/CNY 101 PER PCS)MILD STEEL MULTI FUNCTION CLOTH STAND (RYX-02-020) (QTY: 123 | N21: 4004 | O21: KGS | P21: 434.33413 | Q21: 1739073.9 | R21: 4.8883977 | S21: 19573.144 | T21: 488679.8 | U21: 1232 | W21: MILD | X21: Stand | Y21: Table, kitchen or other household articles of iron or steel | Z21: Steel Household Articles | AA21: Stand | AB21: =IF(INPUT_RAW!B21="","",YEAR(INPUT_RAW!B21)) -> 2025 | AC21: =IF(OR(INPUT_RAW!Q21="",INPUT_RAW!T21=""),"",INPUT_RAW!Q21+INPUT_RAW!T21) -> 2227753.7 | AD21: =IF(INPUT_RAW!Q21="","",IF(INPUT_RAW!Q21=0,0,INPUT_RAW!T21/INPUT_RAW!Q21)) -> 0.28100002
A22: INNSA1 | B22: 2025-09-23 | C22: 301049751 | D22: 73239990 | E22: H2740 STEEL CUTLERY HOLDER (QTY:24960 PCS/ USD 1.46 PER PCS) H2740 STEEL CUTLERY HOLDER (QTY:24960 PCS/ USD 1.46 PER PCS) | N22: 9776 | O22: KGS | P22: 347.60347 | Q22: 3398171.5 | R22: 3.9122506 | S22: 38246.162 | T22: 954886.2 | U22: 24960 | V22: 1.46 | W22: H2740 | X22: Holder | Y22: Table, kitchen or other household articles of iron or steel | Z22: Steel Household Articles | AA22: Holder | AB22: =IF(INPUT_RAW!B22="","",YEAR(INPUT_RAW!B22)) -> 2025 | AC22: =IF(OR(INPUT_RAW!Q22="",INPUT_RAW!T22=""),"",INPUT_RAW!Q22+INPUT_RAW!T22) -> 4353057.7 | AD22: =IF(INPUT_RAW!Q22="","",IF(INPUT_RAW!Q22=0,0,INPUT_RAW!T22/INPUT_RAW!Q22)) -> 0.281
A23: INNSA1 | B23: 2025-09-23 | C23: 301049751 | D23: 73239990 | E23: H2740 STEEL CUTLERY HOLDER (QTY:24960 PCS/ USD 1.46 PER PCS)H2740 STEEL CUTLERY HOLDER (QTY:24960 PCS/ USD 1.46 PER PCS | N23: 9776 | O23: KGS | P23: 347.60342 | Q23: 3398171 | R23: 3.9122501 | S23: 38246.157 | T23: 954886 | U23: 24960 | V23: 1.46 | W23: H2740 | X23: Holder | Y23: Table, kitchen or other household articles of iron or steel | Z23: Steel Household Articles | AA23: Holder | AB23: =IF(INPUT_RAW!B23="","",YEAR(INPUT_RAW!B23)) -> 2025 | AC23: =IF(OR(INPUT_RAW!Q23="",INPUT_RAW!T23=""),"",INPUT_RAW!Q23+INPUT_RAW!T23) -> 4353057 | AD23: =IF(INPUT_RAW!Q23="","",IF(INPUT_RAW!Q23=0,0,INPUT_RAW!T23/INPUT_RAW!Q23)) -> 0.28099998
A24: INNSA1 | B24: 2025-09-20 | C24: 301049751 | D24: 73239990 | E24: HOUSEHOLD STEEL HOOK 3PCS SET (3888) (QTY:153600 SET/USD:0.24 PER SET)HOUSEHOLD STEEL HOOK 3PCS SET (3888) (QTY:153600 SET/USD:0.2 | N24: 5120 | O24: KGS | P24: 660.84275 | Q24: 3383514.9 | R24: 7.437735 | S24: 38081.203 | T24: 1239719.9 | U24: 153600 | V24: 0.24 | W24: HOUSEHOLD | X24: Hook | Y24: Table, kitchen or other household articles of iron or steel | Z24: Steel Household Articles | AA24: Hook | AB24: =IF(INPUT_RAW!B24="","",YEAR(INPUT_RAW!B24)) -> 2025 | AC24: =IF(OR(INPUT_RAW!Q24="",INPUT_RAW!T24=""),"",INPUT_RAW!Q24+INPUT_RAW!T24) -> 4623234.8 | AD24: =IF(INPUT_RAW!Q24="","",IF(INPUT_RAW!Q24=0,0,INPUT_RAW!T24/INPUT_RAW!Q24)) -> 0.36640001
A25: INNSA1 | B25: 2025-09-10 | C25: 301049751 | D25: 73239990 | E25: MILD STEEL MULTI FUNCTION CLOTH STAND (RYX-02-020) (QTY:1,232 PCS/CNY:101.00 PER PCS)MILD STEEL MULTI FUNCTION CLOTH STAND (RYX-02-020) (QTY:1,23 | N25: 4004 | O25: KGS | P25: 427.851 | Q25: 1713115.4 | R25: 4.8073146 | S25: 19248.488 | T25: 627685.5 | U25: 1232 | W25: MILD | X25: Stand | Y25: Table, kitchen or other household articles of iron or steel | Z25: Steel Household Articles | AA25: Stand | AB25: =IF(INPUT_RAW!B25="","",YEAR(INPUT_RAW!B25)) -> 2025 | AC25: =IF(OR(INPUT_RAW!Q25="",INPUT_RAW!T25=""),"",INPUT_RAW!Q25+INPUT_RAW!T25) -> 2340800.9 | AD25: =IF(INPUT_RAW!Q25="","",IF(INPUT_RAW!Q25=0,0,INPUT_RAW!T25/INPUT_RAW!Q25)) -> 0.36640001
A26: INNSA1 | B26: 2025-09-09 | C26: 301049751 | D26: 73239990 | E26: STEEL BASKET BIG (SY-845-4) (QTY:800 PCS/USD:0.9710 PER PCS) STEEL BASKET BIG (SY-845-4) (QTY:800 PCS/USD:0.9710 PER PCS) | N26: 150 | O26: KGS | P26: 499.2998 | Q26: 74894.97 | R26: 5.6101101 | S26: 841.51652 | T26: 27441.5 | U26: 800 | V26: 0.971 | W26: STEEL | X26: Basket | Y26: Table, kitchen or other household articles of iron or steel | Z26: Steel Household Articles | AA26: Basket | AB26: =IF(INPUT_RAW!B26="","",YEAR(INPUT_RAW!B26)) -> 2025 | AC26: =IF(OR(INPUT_RAW!Q26="",INPUT_RAW!T26=""),"",INPUT_RAW!Q26+INPUT_RAW!T26) -> 102336.47 | AD26: =IF(INPUT_RAW!Q26="","",IF(INPUT_RAW!Q26=0,0,INPUT_RAW!T26/INPUT_RAW!Q26)) -> 0.36639977
A27: INNSA1 | B27: 2025-09-05 | C27: 301049751 | D27: 73239990 | E27: MILD STEEL MULTI FUNCTION CLOTH STAND (RYX-02-026-3S) (QTY:1696 PCS/CNY: 81.50 PER PCS)MILD STEEL MULTI FUNCTION CLOTH STAND (RYX-02-026-3S) (QTY | N27: 6614.4 | O27: KGS | P27: 308.04406 | Q27: 2037526.6 | R27: 3.4611692 | S27: 22893.558 | T27: 746549.7 | U27: 1696 | W27: MILD | X27: Stand | Y27: Table, kitchen or other household articles of iron or steel | Z27: Steel Household Articles | AA27: Stand | AB27: =IF(INPUT_RAW!B27="","",YEAR(INPUT_RAW!B27)) -> 2025 | AC27: =IF(OR(INPUT_RAW!Q27="",INPUT_RAW!T27=""),"",INPUT_RAW!Q27+INPUT_RAW!T27) -> 2784076.3 | AD27: =IF(INPUT_RAW!Q27="","",IF(INPUT_RAW!Q27=0,0,INPUT_RAW!T27/INPUT_RAW!Q27)) -> 0.36639997
A28: INNSA1 | B28: 2025-09-02 | C28: 301049751 | D28: 73239990 | E28: SB-12 STEEL TEA STRAINER BIG (QTY:4842 PCS/USD 0.977 PER PCS)SB-12 STEEL TEA STRAINER BIG (QTY:4842 PCS/USD 0.977 PER PCS | N28: 1183.6 | O28: KGS | P28: 381.68437 | Q28: 451761.62 | R28: 4.3422568 | S28: 5139.4951 | T28: 165525.4 | U28: 4842 | V28: 0.977 | W28: SB-12 | X28: Strainer | Y28: Table, kitchen or other household articles of iron or steel | Z28: Steel Household Articles | AA28: Strainer | AB28: =IF(INPUT_RAW!B28="","",YEAR(INPUT_RAW!B28)) -> 2025 | AC28: =IF(OR(INPUT_RAW!Q28="",INPUT_RAW!T28=""),"",INPUT_RAW!Q28+INPUT_RAW!T28) -> 617287.02 | AD28: =IF(INPUT_RAW!Q28="","",IF(INPUT_RAW!Q28=0,0,INPUT_RAW!T28/INPUT_RAW!Q28)) -> 0.36639987
A29: INNSA1 | B29: 2025-09-02 | C29: 301049751 | D29: 73239990 | E29: SY-845-4 STEEL BASKET BIG (QTY 37200 PCS/USD 0.9691 PER PCS) SY-845-4 STEEL BASKET BIG (QTY 37200 PCS/USD 0.9691 PER PCS) | N29: 6975 | O29: KGS | P29: 506.19002 | Q29: 3530675.4 | R29: 5.7587033 | S29: 40166.955 | T29: 1293639.5 | U29: 37200 | V29: 0.9691 | W29: SY-845-4 | X29: Basket | Y29: Table, kitchen or other household articles of iron or steel | Z29: Steel Household Articles | AA29: Basket | AB29: =IF(INPUT_RAW!B29="","",YEAR(INPUT_RAW!B29)) -> 2025 | AC29: =IF(OR(INPUT_RAW!Q29="",INPUT_RAW!T29=""),"",INPUT_RAW!Q29+INPUT_RAW!T29) -> 4824314.9 | AD29: =IF(INPUT_RAW!Q29="","",IF(INPUT_RAW!Q29=0,0,INPUT_RAW!T29/INPUT_RAW!Q29)) -> 0.36640001
A30: INNSA1 | B30: 2025-09-02 | C30: 301049751 | D30: 73239990 | E30: NP-55 STEEL TEA STRAINER (QTY:50400 PCS/USD 0.270 PER PCS) NP-55 STEEL TEA STRAINER (QTY:50400 PCS/USD 0.270 PER PCS) | N30: 2310 | O30: KGS | P30: 562.56491 | Q30: 1299524.9 | R30: 6.4000559 | S30: 14784.129 | T30: 476146 | U30: 50400 | V30: 0.27 | W30: NP-55 | X30: Strainer | Y30: Table, kitchen or other household articles of iron or steel | Z30: Steel Household Articles | AA30: Strainer | AB30: =IF(INPUT_RAW!B30="","",YEAR(INPUT_RAW!B30)) -> 2025 | AC30: =IF(OR(INPUT_RAW!Q30="",INPUT_RAW!T30=""),"",INPUT_RAW!Q30+INPUT_RAW!T30) -> 1775670.9 | AD30: =IF(INPUT_RAW!Q30="","",IF(INPUT_RAW!Q30=0,0,INPUT_RAW!T30/INPUT_RAW!Q30)) -> 0.36640004
A31: INNSA1 | B31: 2025-09-02 | C31: 301049751 | D31: 73239990 | E31: AM-321 STEEL DRAINER (QTY:21648 PCS/USD 0.702 PER PCS) AM-321 STEEL DRAINER (QTY:21648 PCS/USD 0.702 PER PCS) | N31: 2976.6 | O31: KGS | P31: 487.55641 | Q31: 1451260.4 | R31: 5.5467168 | S31: 16510.357 | T31: 531741.8 | U31: 21648 | V31: 0.702 | W31: AM-321 | Y31: Table, kitchen or other household articles of iron or steel | Z31: Steel Household Articles | AA31: Household Article | AB31: =IF(INPUT_RAW!B31="","",YEAR(INPUT_RAW!B31)) -> 2025 | AC31: =IF(OR(INPUT_RAW!Q31="",INPUT_RAW!T31=""),"",INPUT_RAW!Q31+INPUT_RAW!T31) -> 1983002.2 | AD31: =IF(INPUT_RAW!Q31="","",IF(INPUT_RAW!Q31=0,0,INPUT_RAW!T31/INPUT_RAW!Q31)) -> 0.36639999
A32: INNSA1 | B32: 2025-08-30 | C32: 301049751 | D32: 73239990 | E32: STEEL SALT BOTTLE (NP-19) (QTY: 36180 PC/USD 0.446 PER PC) STEEL SALT BOTTLE (NP-19) (QTY: 36180 PC/USD 0.446 PER PC) | N32: 5628 | O32: KGS | P32: 271.19431 | Q32: 1526281.6 | R32: 3.0852595 | S32: 17363.841 | T32: 559229.5 | U32: 36180 | V32: 0.446 | W32: STEEL | X32: Bottle | Y32: Table, kitchen or other household articles of iron or steel | Z32: Steel Household Articles | AA32: Bottle | AB32: =IF(INPUT_RAW!B32="","",YEAR(INPUT_RAW!B32)) -> 2025 | AC32: =IF(OR(INPUT_RAW!Q32="",INPUT_RAW!T32=""),"",INPUT_RAW!Q32+INPUT_RAW!T32) -> 2085511.1 | AD32: =IF(INPUT_RAW!Q32="","",IF(INPUT_RAW!Q32=0,0,INPUT_RAW!T32/INPUT_RAW!Q32)) -> 0.36639995
A33: INNSA1 | B33: 2025-08-29 | C33: 301049751 | D33: 73231000 | E33: STEEL SCRUBBER 6PCS SET (OKS-4156) (QTY:98,400 SET/USD:0.228PER SET)STEEL SCRUBBER 6PCS SET (OKS-4156) (QTY:98,400 SET/USD:0.228 | N33: 8856 | O33: KGS | P33: 242.06265 | Q33: 2143706.8 | R33: 2.7538412 | S33: 24388.018 | T33: 942373.5 | U33: 98400 | V33: 0.228 | W33: STEEL | X33: Scrubber | Y33: Stainless steel scouring pads and similar | Z33: Cleaning Supplies | AA33: Scrubber | AB33: =IF(INPUT_RAW!B33="","",YEAR(INPUT_RAW!B33)) -> 2025 | AC33: =IF(OR(INPUT_RAW!Q33="",INPUT_RAW!T33=""),"",INPUT_RAW!Q33+INPUT_RAW!T33) -> 3086080.3 | AD33: =IF(INPUT_RAW!Q33="","",IF(INPUT_RAW!Q33=0,0,INPUT_RAW!T33/INPUT_RAW!Q33)) -> 0.4396
A34: INNSA1 | B34: 2025-08-23 | C34: 301049751 | D34: 73231000 | E34: STEEL SCRUBBER (8001-12) (QTY:263520 PCS/USD:0.078 PER PCS) STEEL SCRUBBER (8001-12) (QTY:263520 PCS/USD:0.078 PER PCS) | N34: 4758 | O34: KGS | P34: 399.76611 | Q34: 1902087.1 | R34: 4.5479648 | S34: 21639.217 | T34: 836157.4 | U34: 263520 | V34: 0.078 | W34: STEEL | X34: Scrubber | Y34: Stainless steel scouring pads and similar | Z34: Cleaning Supplies | AA34: Scrubber | AB34: =IF(INPUT_RAW!B34="","",YEAR(INPUT_RAW!B34)) -> 2025 | AC34: =IF(OR(INPUT_RAW!Q34="",INPUT_RAW!T34=""),"",INPUT_RAW!Q34+INPUT_RAW!T34) -> 2738244.5 | AD34: =IF(INPUT_RAW!Q34="","",IF(INPUT_RAW!Q34=0,0,INPUT_RAW!T34/INPUT_RAW!Q34)) -> 0.43959994
A35: INNSA1 | B35: 2025-08-23 | C35: 301049751 | D35: 73231000 | E35: STEEL SCRUBBER 6 PCS SET (GT001) (QTY:1260 PCS/USD:0.238 PERPCS)STEEL SCRUBBER 6 PCS SET (GT001) (QTY:1260 PCS/USD:0.238 PER | N35: 180 | O35: KGS | P35: 154.16906 | Q35: 27750.43 | R35: 1.7539142 | S35: 315.70455 | T35: 12199.1 | U35: 1260 | V35: 0.238 | W35: STEEL | X35: Scrubber | Y35: Stainless steel scouring pads and similar | Z35: Cleaning Supplies | AA35: Scrubber | AB35: =IF(INPUT_RAW!B35="","",YEAR(INPUT_RAW!B35)) -> 2025 | AC35: =IF(OR(INPUT_RAW!Q35="",INPUT_RAW!T35=""),"",INPUT_RAW!Q35+INPUT_RAW!T35) -> 39949.53 | AD35: =IF(INPUT_RAW!Q35="","",IF(INPUT_RAW!Q35=0,0,INPUT_RAW!T35/INPUT_RAW!Q35)) -> 0.4396004
A36: INNSA1 | B36: 2025-08-20 | C36: 301049751 | D36: 73239990 | E36: STEEL SPRINKLER (AM-430) (QTY: 30072 PCS/USD 0.578 PER PCS) STEEL SPRINKLER (AM-430) (QTY: 30072 PCS/USD 0.578 PER PCS) | N36: 5012 | O36: KGS | P36: 326.07507 | Q36: 1634288.3 | R36: 3.6803056 | S36: 18445.692 | T36: 598803.3 | U36: 30072 | V36: 0.578 | W36: STEEL | Y36: Table, kitchen or other household articles of iron or steel | Z36: Steel Household Articles | AA36: Household Article | AB36: =IF(INPUT_RAW!B36="","",YEAR(INPUT_RAW!B36)) -> 2025 | AC36: =IF(OR(INPUT_RAW!Q36="",INPUT_RAW!T36=""),"",INPUT_RAW!Q36+INPUT_RAW!T36) -> 2233091.6 | AD36: =IF(INPUT_RAW!Q36="","",IF(INPUT_RAW!Q36=0,0,INPUT_RAW!T36/INPUT_RAW!Q36)) -> 0.36640005
A37: INNSA1 | B37: 2025-08-20 | C37: 301049751 | D37: 73239990 | E37: STEEL SALT BOTTLE (NP-19) (QTY: 36000 PCS/USD 0.445 PER PCS) STEEL SALT BOTTLE (NP-19) (QTY: 36000 PCS/USD 0.445 PER PCS) | N37: 5600 | O37: KGS | P37: 268.97564 | Q37: 1506263.6 | R37: 3.0358425 | S37: 17000.718 | T37: 551895 | U37: 36000 | V37: 0.445 | W37: STEEL | X37: Bottle | Y37: Table, kitchen or other household articles of iron or steel | Z37: Steel Household Articles | AA37: Bottle | AB37: =IF(INPUT_RAW!B37="","",YEAR(INPUT_RAW!B37)) -> 2025 | AC37: =IF(OR(INPUT_RAW!Q37="",INPUT_RAW!T37=""),"",INPUT_RAW!Q37+INPUT_RAW!T37) -> 2058158.6 | AD37: =IF(INPUT_RAW!Q37="","",IF(INPUT_RAW!Q37=0,0,INPUT_RAW!T37/INPUT_RAW!Q37)) -> 0.36640001
A38: INNSA1 | B38: 2025-08-16 | C38: 301049751 | D38: 73231000 | E38: STEEL SCRUBBER 6PCS SET (OKS-4156) (QTY:98,400 SET/USD:0.228PER SET)STEEL SCRUBBER 6PCS SET (OKS-4156) (QTY:98,400 SET/USD:0.228 | N38: 8856 | O38: KGS | P38: 235.98644 | Q38: 2089895.9 | R38: 2.6635038 | S38: 23587.99 | T38: 918718.2 | U38: 98400 | V38: 0.228 | W38: STEEL | X38: Scrubber | Y38: Stainless steel scouring pads and similar | Z38: Cleaning Supplies | AA38: Scrubber | AB38: =IF(INPUT_RAW!B38="","",YEAR(INPUT_RAW!B38)) -> 2025 | AC38: =IF(OR(INPUT_RAW!Q38="",INPUT_RAW!T38=""),"",INPUT_RAW!Q38+INPUT_RAW!T38) -> 3008614.1 | AD38: =IF(INPUT_RAW!Q38="","",IF(INPUT_RAW!Q38=0,0,INPUT_RAW!T38/INPUT_RAW!Q38)) -> 0.43959999
A39: INNSA1 | B39: 2025-08-07 | C39: 301049751 | D39: 73239990 | E39: STEEL BASKET SQUARE (SY-845-6) (QTY: 4400 PCS/USD 0.702 PERPCS)STEEL BASKET SQUARE (SY-845-6) (QTY: 4400 PCS/USD 0.702 PER | N39: 660 | O39: KGS | P39: 436.13305 | Q39: 287847.81 | R39: 5.0245743 | S39: 3316.219 | T39: 105467.5 | U39: 4400 | V39: 0.702 | W39: STEEL | X39: Basket | Y39: Table, kitchen or other household articles of iron or steel | Z39: Steel Household Articles | AA39: Basket | AB39: =IF(INPUT_RAW!B39="","",YEAR(INPUT_RAW!B39)) -> 2025 | AC39: =IF(OR(INPUT_RAW!Q39="",INPUT_RAW!T39=""),"",INPUT_RAW!Q39+INPUT_RAW!T39) -> 393315.31 | AD39: =IF(INPUT_RAW!Q39="","",IF(INPUT_RAW!Q39=0,0,INPUT_RAW!T39/INPUT_RAW!Q39)) -> 0.36640022
A40: INNSA1 | B40: 2025-08-01 | C40: 301049751 | D40: 73231000 | E40: STEEL SCRUBBER 2 PCS SET (8001-2) (QTY:336000 SET/USD:0.139PER SET)STEEL SCRUBBER 2 PCS SET (8001-2) (QTY:336000 SET/USD:0.139 | N40: 9800 | O40: KGS | P40: 438.07306 | Q40: 4293116 | R40: 5.0469247 | S40: 49459.862 | T40: 1887253.8 | U40: 336000 | V40: 0.139 | W40: STEEL | X40: Scrubber | Y40: Stainless steel scouring pads and similar | Z40: Cleaning Supplies | AA40: Scrubber | AB40: =IF(INPUT_RAW!B40="","",YEAR(INPUT_RAW!B40)) -> 2025 | AC40: =IF(OR(INPUT_RAW!Q40="",INPUT_RAW!T40=""),"",INPUT_RAW!Q40+INPUT_RAW!T40) -> 6180369.8 | AD40: =IF(INPUT_RAW!Q40="","",IF(INPUT_RAW!Q40=0,0,INPUT_RAW!T40/INPUT_RAW!Q40)) -> 0.4396
...

Sheet HSN_MAPPING
A1: HSN | B1: DESCRIPTION | C1: MAIN_CATEGORY | D1: SUGGESTED_SUBCATEGORY
A2: 73239990 | B2: Table, kitchen or other household articles of iron or steel | C2: Steel Household Articles | D2: Household Article
A3: 73231000 | B3: Stainless steel scouring pads and similar | C3: Cleaning Supplies | D3: Scrubber
A4: 73239390 | B4: Table, kitchen or other household articles of stainless steel | C4: Stainless Steel Household Articles | D4: Kitchenware
A5: 73269090 | B5: Articles of iron or steel, other | C5: Iron/Steel Wire Products | D5: Other
A6: 73211100 | B6: Stoves and ranges | C6: Kitchen Accessories | D6: Appliance
A7: 73239400 | B7: Other stainless steel household articles | C7: Stainless Steel Household Articles | D7: Other
A8: 73239910 | B8: Other kitchen articles | C8: Steel Household Articles | D8: Kitchenware
A9: 73239310 | B9: Spoons and forks stainless | C9: Stainless Steel Household Articles | D9: Cutlery
A10: 73239300 | B10: Other household articles of stainless steel | C10: Stainless Steel Household Articles | D10: Other
A11: 73241100 | B11: Grated, powdered metal | C11: Others | D11: Other

Sheet YEAR_SUMMARY
A1: YEAR | B1: TOTAL_VALUE_INR | C1: DUTY_PAID_INR | D1: GRAND_TOTAL_INR | E1: YOY_GROWTH_PCT
A2: 2017 | B2: =SUMIFS(CLEANED_DATA!Q2:'CLEANED_DATA'!Q2080,CLEANED_DATA!AB2:'CLEANED_DATA'!AB2080,A2) -> 1.5824324e+08 | C2: =SUMIFS(CLEANED_DATA!T2:'CLEANED_DATA'!T2080,CLEANED_DATA!AB2:'CLEANED_DATA'!AB2080,A2) -> 32749950 | D2: =SUMIFS(CLEANED_DATA!AC2:'CLEANED_DATA'!AC2080,CLEANED_DATA!AB2:'CLEANED_DATA'!AB2080,A2) -> 1.9099319e+08
A3: 2018 | B3: =SUMIFS(CLEANED_DATA!Q2:'CLEANED_DATA'!Q2080,CLEANED_DATA!AB2:'CLEANED_DATA'!AB2080,A3) -> 3.3422649e+08 | C3: =SUMIFS(CLEANED_DATA!T2:'CLEANED_DATA'!T2080,CLEANED_DATA!AB2:'CLEANED_DATA'!AB2080,A3) -> 82490492 | D3: =SUMIFS(CLEANED_DATA!AC2:'CLEANED_DATA'!AC2080,CLEANED_DATA!AB2:'CLEANED_DATA'!AB2080,A3) -> 4.1671698e+08 | E3: =IF(B2=0,"",(B3-B2)/B2) -> 1.1121059
A4: 2019 | B4: =SUMIFS(CLEANED_DATA!Q2:'CLEANED_DATA'!Q2080,CLEANED_DATA!AB2:'CLEANED_DATA'!AB2080,A4) -> 4.2140296e+08 | C4: =SUMIFS(CLEANED_DATA!T2:'CLEANED_DATA'!T2080,CLEANED_DATA!AB2:'CLEANED_DATA'!AB2080,A4) -> 1.040222e+08 | D4: =SUMIFS(CLEANED_DATA!AC2:'CLEANED_DATA'!AC2080,CLEANED_DATA!AB2:'CLEANED_DATA'!AB2080,A4) -> 5.2542517e+08 | E4: =IF(B3=0,"",(B4-B3)/B3) -> 0.26083053
A5: 2020 | B5: =SUMIFS(CLEANED_DATA!Q2:'CLEANED_DATA'!Q2080,CLEANED_DATA!AB2:'CLEANED_DATA'!AB2080,A5) -> 3.492895e+08 | C5: =SUMIFS(CLEANED_DATA!T2:'CLEANED_DATA'!T2080,CLEANED_DATA!AB2:'CLEANED_DATA'!AB2080,A5) -> 1.2030663e+08 | D5: =SUMIFS(CLEANED_DATA!AC2:'CLEANED_DATA'!AC2080,CLEANED_DATA!AB2:'CLEANED_DATA'!AB2080,A5) -> 4.6959613e+08 | E5: =IF(B4=0,"",(B5-B4)/B4) -> -0.17112709
A6: 2021 | B6: =SUMIFS(CLEANED_DATA!Q2:'CLEANED_DATA'!Q2080,CLEANED_DATA!AB2:'CLEANED_DATA'!AB2080,A6) -> 4.8739781e+08 | C6: =SUMIFS(CLEANED_DATA!T2:'CLEANED_DATA'!T2080,CLEANED_DATA!AB2:'CLEANED_DATA'!AB2080,A6) -> 1.8160358e+08 | D6: =SUMIFS(CLEANED_DATA!AC2:'CLEANED_DATA'!AC2080,CLEANED_DATA!AB2:'CLEANED_DATA'!AB2080,A6) -> 6.6900139e+08 | E6: =IF(B5=0,"",(B6-B5)/B5) -> 0.39539783
A7: 2022 | B7: =SUMIFS(CLEANED_DATA!Q2:'CLEANED_DATA'!Q2080,CLEANED_DATA!AB2:'CLEANED_DATA'!AB2080,A7) -> 7.5432377e+08 | C7: =SUMIFS(CLEANED_DATA!T2:'CLEANED_DATA'!T2080,CLEANED_DATA!AB2:'CLEANED_DATA'!AB2080,A7) -> 2.804435e+08 | D7: =SUMIFS(CLEANED_DATA!AC2:'CLEANED_DATA'!AC2080,CLEANED_DATA!AB2:'CLEANED_DATA'!AB2080,A7) -> 1.0347673e+09 | E7: =IF(B6=0,"",(B7-B6)/B6) -> 0.54765523
A8: 2023 | B8: =SUMIFS(CLEANED_DATA!Q2:'CLEANED_DATA'!Q2080,CLEANED_DATA!AB2:'CLEANED_DATA'!AB2080,A8) -> 8.704074e+08 | C8: =SUMIFS(CLEANED_DATA!T2:'CLEANED_DATA'!T2080,CLEANED_DATA!AB2:'CLEANED_DATA'!AB2080,A8) -> 3.2152181e+08 | D8: =SUMIFS(CLEANED_DATA!AC2:'CLEANED_DATA'!AC2080,CLEANED_DATA!AB2:'CLEANED_DATA'!AB2080,A8) -> 1.1919292e+09 | E8: =IF(B7=0,"",(B8-B7)/B7) -> 0.15389098
A9: 2024 | B9: =SUMIFS(CLEANED_DATA!Q2:'CLEANED_DATA'!Q2080,CLEANED_DATA!AB2:'CLEANED_DATA'!AB2080,A9) -> 4.2551804e+08 | C9: =SUMIFS(CLEANED_DATA!T2:'CLEANED_DATA'!T2080,CLEANED_DATA!AB2:'CLEANED_DATA'!AB2080,A9) -> 1.6074949e+08 | D9: =SUMIFS(CLEANED_DATA!AC2:'CLEANED_DATA'!AC2080,CLEANED_DATA!AB2:'CLEANED_DATA'!AB2080,A9) -> 5.8626753e+08 | E9: =IF(B8=0,"",(B9-B8)/B8) -> -0.51112773
A10: 2025 | B10: =SUMIFS(CLEANED_DATA!Q2:'CLEANED_DATA'!Q2080,CLEANED_DATA!AB2:'CLEANED_DATA'!AB2080,A10) -> 3.9312917e+08 | C10: =SUMIFS(CLEANED_DATA!T2:'CLEANED_DATA'!T2080,CLEANED_DATA!AB2:'CLEANED_DATA'!AB2080,A10) -> 1.4612916e+08 | D10: =SUMIFS(CLEANED_DATA!AC2:'CLEANED_DATA'!AC2080,CLEANED_DATA!AB2:'CLEANED_DATA'!AB2080,A10) -> 5.3925833e+08 | E10: =IF(B9=0,"",(B10-B9)/B9) -> -0.076116314

Sheet HSN_SUMMARY_V2
A1: HSN | B1: HSN_DESCRIPTION | C1: MAIN_CATEGORY | D1: SUB_CATEGORY | E1: TOTAL_VALUE_INR | F1: DUTY_PAID_INR | G1: GRAND_TOTAL_INR | H1: %_CONTRIBUTION
A2: 73231000 | B2: Stainless steel scouring pads and similar | C2: Cleaning Supplies | D2: Scrubber | E2: =SUMIFS(CLEANED_DATA!Q2:'CLEANED_DATA'!Q2080,CLEANED_DATA!D2:'CLEANED_DATA'!D2080,A2) -> 3.353318e+08 | F2: =SUMIFS(CLEANED_DATA!T2:'CLEANED_DATA'!T2080,CLEANED_DATA!D2:'CLEANED_DATA'!D2080,A2) -> 1.3858841e+08 | G2: =SUMIFS(CLEANED_DATA!AC2:'CLEANED_DATA'!AC2080,CLEANED_DATA!D2:'CLEANED_DATA'!D2080,A2) -> 4.7392021e+08 | H2: =IF($E$6=0,0,E2/$E$6) -> 0.079956301
A3: 73239390 | B3: Table, kitchen or other household articles of stainless steel | C3: Stainless Steel Household Articles | D3: Kitchenware | E3: =SUMIFS(CLEANED_DATA!Q2:'CLEANED_DATA'!Q2080,CLEANED_DATA!D2:'CLEANED_DATA'!D2080,A3) -> 15387697 | F3: =SUMIFS(CLEANED_DATA!T2:'CLEANED_DATA'!T2080,CLEANED_DATA!D2:'CLEANED_DATA'!D2080,A3) -> 4195325.1 | G3: =SUMIFS(CLEANED_DATA!AC2:'CLEANED_DATA'!AC2080,CLEANED_DATA!D2:'CLEANED_DATA'!D2080,A3) -> 19583022 | H3: =IF($E$6=0,0,E3/$E$6) -> 0.0036690326
A4: 73239990 | B4: Table, kitchen or other household articles of iron or steel | C4: Steel Household Articles | D4: Household Article | E4: =SUMIFS(CLEANED_DATA!Q2:'CLEANED_DATA'!Q2080,CLEANED_DATA!D2:'CLEANED_DATA'!D2080,A4) -> 3.8432189e+09 | F4: =SUMIFS(CLEANED_DATA!T2:'CLEANED_DATA'!T2080,CLEANED_DATA!D2:'CLEANED_DATA'!D2080,A4) -> 1.2872331e+09 | G4: =SUMIFS(CLEANED_DATA!AC2:'CLEANED_DATA'!AC2080,CLEANED_DATA!D2:'CLEANED_DATA'!D2080,A4) -> 5.130452e+09 | H4: =IF($E$6=0,0,E4/$E$6) -> 0.91637467
D6: Overall Grand Total | E6: =SUM(E2:E4) -> 4.1939384e+09

Sheet CATEGORY_SUMMARY
A1: MAIN_CATEGORY | B1: TOTAL_VALUE_INR | C1: DUTY_PAID_INR | D1: GRAND_TOTAL_INR | E1: %_CONTRIBUTION
A2: Cleaning Supplies | B2: =SUMIFS(CLEANED_DATA!Q2:'CLEANED_DATA'!Q2080,CLEANED_DATA!Z2:'CLEANED_DATA'!Z2080,A2) -> 3.353318e+08 | C2: =SUMIFS(CLEANED_DATA!T2:'CLEANED_DATA'!T2080,CLEANED_DATA!Z2:'CLEANED_DATA'!Z2080,A2) -> 1.3858841e+08 | D2: =SUMIFS(CLEANED_DATA!AC2:'CLEANED_DATA'!AC2080,CLEANED_DATA!Z2:'CLEANED_DATA'!Z2080,A2) -> 4.7392021e+08 | E2: =IF($B$6=0,0,D2/$B$6) -> 0.084268134
A3: Stainless Steel Household Articles | B3: =SUMIFS(CLEANED_DATA!Q2:'CLEANED_DATA'!Q2080,CLEANED_DATA!Z2:'CLEANED_DATA'!Z2080,A3) -> 15387697 | C3: =SUMIFS(CLEANED_DATA!T2:'CLEANED_DATA'!T2080,CLEANED_DATA!Z2:'CLEANED_DATA'!Z2080,A3) -> 4195325.1 | D3: =SUMIFS(CLEANED_DATA!AC2:'CLEANED_DATA'!AC2080,CLEANED_DATA!Z2:'CLEANED_DATA'!Z2080,A3) -> 19583022 | E3: =IF($B$6=0,0,D3/$B$6) -> 0.0034820728
A4: Steel Household Articles | B4: =SUMIFS(CLEANED_DATA!Q2:'CLEANED_DATA'!Q2080,CLEANED_DATA!Z2:'CLEANED_DATA'!Z2080,A4) -> 3.8432189e+09 | C4: =SUMIFS(CLEANED_DATA!T2:'CLEANED_DATA'!T2080,CLEANED_DATA!Z2:'CLEANED_DATA'!Z2080,A4) -> 1.2872331e+09 | D4: =SUMIFS(CLEANED_DATA!AC2:'CLEANED_DATA'!AC2080,CLEANED_DATA!Z2:'CLEANED_DATA'!Z2080,A4) -> 5.130452e+09 | E4: =IF($B$6=0,0,D4/$B$6) -> 0.91224979
A6: Overall Grand Total | B6: =SUM(D2:D4) -> 5.6239552e+09

Sheet MODEL_ANALYSIS_V2
A1: MODEL | B1: TOTAL_QTY | C1: TOTAL_VALUE_INR | D1: AVG_UNIT_PRICE_USD | E1: TOTAL_WITH_DUTY_INR
A2: 03-0271 | B2: =SUMIFS(CLEANED_DATA!U2:'CLEANED_DATA'!U2080,CLEANED_DATA!W2:'CLEANED_DATA'!W2080,A2) -> 1800 | C2: =SUMIFS(CLEANED_DATA!Q2:'CLEANED_DATA'!Q2080,CLEANED_DATA!W2:'CLEANED_DATA'!W2080,A2) -> 1499255.1 | D2: =IF(B2=0,0,SUMIFS(CLEANED_DATA!V2:'CLEANED_DATA'!V2080,CLEANED_DATA!W2:'CLEANED_DATA'!W2080,A2)/B2) -> 0 | E2: =C2+0 -> 1499255.1
A3: 03-027I | B3: =SUMIFS(CLEANED_DATA!U2:'CLEANED_DATA'!U2080,CLEANED_DATA!W2:'CLEANED_DATA'!W2080,A3) -> 34584 | C3: =SUMIFS(CLEANED_DATA!Q2:'CLEANED_DATA'!Q2080,CLEANED_DATA!W2:'CLEANED_DATA'!W2080,A3) -> 30016788 | D3: =IF(B3=0,0,SUMIFS(CLEANED_DATA!V2:'CLEANED_DATA'!V2080,CLEANED_DATA!W2:'CLEANED_DATA'!W2080,A3)/B3) -> 0 | E3: =C3+0 -> 30016788
A4: 2628 | B4: =SUMIFS(CLEANED_DATA!U2:'CLEANED_DATA'!U2080,CLEANED_DATA!W2:'CLEANED_DATA'!W2080,A4) -> 1098288 | C4: =SUMIFS(CLEANED_DATA!Q2:'CLEANED_DATA'!Q2080,CLEANED_DATA!W2:'CLEANED_DATA'!W2080,A4) -> 39356895 | D4: =IF(B4=0,0,SUMIFS(CLEANED_DATA!V2:'CLEANED_DATA'!V2080,CLEANED_DATA!W2:'CLEANED_DATA'!W2080,A4)/B4) -> 3.1758519e-06 | E4: =C4+0 -> 39356895
A5: 320F | B5: =SUMIFS(CLEANED_DATA!U2:'CLEANED_DATA'!U2080,CLEANED_DATA!W2:'CLEANED_DATA'!W2080,A5) -> 480 | C5: =SUMIFS(CLEANED_DATA!Q2:'CLEANED_DATA'!Q2080,CLEANED_DATA!W2:'CLEANED_DATA'!W2080,A5) -> 17971.48 | D5: =IF(B5=0,0,SUMIFS(CLEANED_DATA!V2:'CLEANED_DATA'!V2080,CLEANED_DATA!W2:'CLEANED_DATA'!W2080,A5)/B5) -> 0.00087645833 | E5: =C5+0 -> 17971.48
A6: 3888-HOUSEHOLD | B6: =SUMIFS(CLEANED_DATA!U2:'CLEANED_DATA'!U2080,CLEANED_DATA!W2:'CLEANED_DATA'!W2080,A6) -> 208512 | C6: =SUMIFS(CLEANED_DATA!Q2:'CLEANED_DATA'!Q2080,CLEANED_DATA!W2:'CLEANED_DATA'!W2080,A6) -> 5099049.9 | D6: =IF(B6=0,0,SUMIFS(CLEANED_DATA!V2:'CLEANED_DATA'!V2080,CLEANED_DATA!W2:'CLEANED_DATA'!W2080,A6)/B6) -> 1.3764196e-06 | E6: =C6+0 -> 5099049.9
A7: 580F | B7: =SUMIFS(CLEANED_DATA!U2:'CLEANED_DATA'!U2080,CLEANED_DATA!W2:'CLEANED_DATA'!W2080,A7) -> 480 | C7: =SUMIFS(CLEANED_DATA!Q2:'CLEANED_DATA'!Q2080,CLEANED_DATA!W2:'CLEANED_DATA'!W2080,A7) -> 32947.42 | D7: =IF(B7=0,0,SUMIFS(CLEANED_DATA!V2:'CLEANED_DATA'!V2080,CLEANED_DATA!W2:'CLEANED_DATA'!W2080,A7)/B7) -> 0.001606875 | E7: =C7+0 -> 32947.42
A8: 6527 | B8: =SUMIFS(CLEANED_DATA!U2:'CLEANED_DATA'!U2080,CLEANED_DATA!W2:'CLEANED_DATA'!W2080,A8) -> 153600 | C8: =SUMIFS(CLEANED_DATA!Q2:'CLEANED_DATA'!Q2080,CLEANED_DATA!W2:'CLEANED_DATA'!W2080,A8) -> 25939901 | D8: =IF(B8=0,0,SUMIFS(CLEANED_DATA!V2:'CLEANED_DATA'!V2080,CLEANED_DATA!W2:'CLEANED_DATA'!W2080,A8)/B8) -> 7.7994792e-05 | E8: =C8+0 -> 25939901
A9: 6561 | B9: =SUMIFS(CLEANED_DATA!U2:'CLEANED_DATA'!U2080,CLEANED_DATA!W2:'CLEANED_DATA'!W2080,A9) -> 86040 | C9: =SUMIFS(CLEANED_DATA!Q2:'CLEANED_DATA'!Q2080,CLEANED_DATA!W2:'CLEANED_DATA'!W2080,A9) -> 19235683 | D9: =IF(B9=0,0,SUMIFS(CLEANED_DATA!V2:'CLEANED_DATA'!V2080,CLEANED_DATA!W2:'CLEANED_DATA'!W2080,A9)/B9) -> 0.00012203626 | E9: =C9+0 -> 19235683
A10: 6578 | B10: =SUMIFS(CLEANED_DATA!U2:'CLEANED_DATA'!U2080,CLEANED_DATA!W2:'CLEANED_DATA'!W2080,A10) -> 113760 | C10: =SUMIFS(CLEANED_DATA!Q2:'CLEANED_DATA'!Q2080,CLEANED_DATA!W2:'CLEANED_DATA'!W2080,A10) -> 17419237 | D10: =IF(B10=0,0,SUMIFS(CLEANED_DATA!V2:'CLEANED_DATA'!V2080,CLEANED_DATA!W2:'CLEANED_DATA'!W2080,A10)/B10) -> 4.7468354e-05 | E10: =C10+0 -> 17419237
A11: 6581 | B11: =SUMIFS(CLEANED_DATA!U2:'CLEANED_DATA'!U2080,CLEANED_DATA!W2:'CLEANED_DATA'!W2080,A11) -> 222600 | C11: =SUMIFS(CLEANED_DATA!Q2:'CLEANED_DATA'!Q2080,CLEANED_DATA!W2:'CLEANED_DATA'!W2080,A11) -> 18078745 | D11: =IF(B11=0,0,SUMIFS(CLEANED_DATA!V2:'CLEANED_DATA'!V2080,CLEANED_DATA!W2:'CLEANED_DATA'!W2080,A11)/B11) -> 1.3162624e-05 | E11: =C11+0 -> 18078745
A12: 6587 | B12: =SUMIFS(CLEANED_DATA!U2:'CLEANED_DATA'!U2080,CLEANED_DATA!W2:'CLEANED_DATA'!W2080,A12) -> 19920 | C12: =SUMIFS(CLEANED_DATA!Q2:'CLEANED_DATA'!Q2080,CLEANED_DATA!W2:'CLEANED_DATA'!W2080,A12) -> 2844087.6 | D12: =IF(B12=0,0,SUMIFS(CLEANED_DATA!V2:'CLEANED_DATA'!V2080,CLEANED_DATA!W2:'CLEANED_DATA'!W2080,A12)/B12) -> 8.684739e-05 | E12: =C12+0 -> 2844087.6
A13: 6856 | B13: =SUMIFS(CLEANED_DATA!U2:'CLEANED_DATA'!U2080,CLEANED_DATA!W2:'CLEANED_DATA'!W2080,A13) -> 85536 | C13: =SUMIFS(CLEANED_DATA!Q2:'CLEANED_DATA'!Q2080,CLEANED_DATA!W2:'CLEANED_DATA'!W2080,A13) -> 4635679.6 | D13: =IF(B13=0,0,SUMIFS(CLEANED_DATA!V2:'CLEANED_DATA'!V2080,CLEANED_DATA!W2:'CLEANED_DATA'!W2080,A13)/B13) -> 1.5432099e-05 | E13: =C13+0 -> 4635679.6
A14: 6857 | B14: =SUMIFS(CLEANED_DATA!U2:'CLEANED_DATA'!U2080,CLEANED_DATA!W2:'CLEANED_DATA'!W2080,A14) -> 100440 | C14: =SUMIFS(CLEANED_DATA!Q2:'CLEANED_DATA'!Q2080,CLEANED_DATA!W2:'CLEANED_DATA'!W2080,A14) -> 6586953 | D14: =IF(B14=0,0,SUMIFS(CLEANED_DATA!V2:'CLEANED_DATA'!V2080,CLEANED_DATA!W2:'CLEANED_DATA'!W2080,A14)/B14) -> 1.602947e-05 | E14: =C14+0 -> 6586953
A15: 6862 | B15: =SUMIFS(CLEANED_DATA!U2:'CLEANED_DATA'!U2080,CLEANED_DATA!W2:'CLEANED_DATA'!W2080,A15) -> 132216 | C15: =SUMIFS(CLEANED_DATA!Q2:'CLEANED_DATA'!Q2080,CLEANED_DATA!W2:'CLEANED_DATA'!W2080,A15) -> 17573634 | D15: =IF(B15=0,0,SUMIFS(CLEANED_DATA!V2:'CLEANED_DATA'!V2080,CLEANED_DATA!W2:'CLEANED_DATA'!W2080,A15)/B15) -> 6.0280148e-05 | E15: =C15+0 -> 17573634
A16: 6900 | B16: =SUMIFS(CLEANED_DATA!U2:'CLEANED_DATA'!U2080,CLEANED_DATA!W2:'CLEANED_DATA'!W2080,A16) -> 91200 | C16: =SUMIFS(CLEANED_DATA!Q2:'CLEANED_DATA'!Q2080,CLEANED_DATA!W2:'CLEANED_DATA'!W2080,A16) -> 6681079 | D16: =IF(B16=0,0,SUMIFS(CLEANED_DATA!V2:'CLEANED_DATA'!V2080,CLEANED_DATA!W2:'CLEANED_DATA'!W2080,A16)/B16) -> 9.1008772e-06 | E16: =C16+0 -> 6681079
A17: 6901 | B17: =SUMIFS(CLEANED_DATA!U2:'CLEANED_DATA'!U2080,CLEANED_DATA!W2:'CLEANED_DATA'!W2080,A17) -> 275304 | C17: =SUMIFS(CLEANED_DATA!Q2:'CLEANED_DATA'!Q2080,CLEANED_DATA!W2:'CLEANED_DATA'!W2080,A17) -> 24363335 | D17: =IF(B17=0,0,SUMIFS(CLEANED_DATA!V2:'CLEANED_DATA'!V2080,CLEANED_DATA!W2:'CLEANED_DATA'!W2080,A17)/B17) -> 1.8742917e-05 | E17: =C17+0 -> 24363335
A18: 8001- | B18: =SUMIFS(CLEANED_DATA!U2:'CLEANED_DATA'!U2080,CLEANED_DATA!W2:'CLEANED_DATA'!W2080,A18) -> 2 | C18: =SUMIFS(CLEANED_DATA!Q2:'CLEANED_DATA'!Q2080,CLEANED_DATA!W2:'CLEANED_DATA'!W2080,A18) -> 1683904.4 | D18: =IF(B18=0,0,SUMIFS(CLEANED_DATA!V2:'CLEANED_DATA'!V2080,CLEANED_DATA!W2:'CLEANED_DATA'!W2080,A18)/B18) -> 0 | E18: =C18+0 -> 1683904.4
A19: 8001-1PCS | B19: =SUMIFS(CLEANED_DATA!U2:'CLEANED_DATA'!U2080,CLEANED_DATA!W2:'CLEANED_DATA'!W2080,A19) -> 3 | C19: =SUMIFS(CLEANED_DATA!Q2:'CLEANED_DATA'!Q2080,CLEANED_DATA!W2:'CLEANED_DATA'!W2080,A19) -> 4578915 | D19: =IF(B19=0,0,SUMIFS(CLEANED_DATA!V2:'CLEANED_DATA'!V2080,CLEANED_DATA!W2:'CLEANED_DATA'!W2080,A19)/B19) -> 0 | E19: =C19+0 -> 4578915
A20: 8001-2 | B20: =SUMIFS(CLEANED_DATA!U2:'CLEANED_DATA'!U2080,CLEANED_DATA!W2:'CLEANED_DATA'!W2080,A20) -> 1334668 | C20: =SUMIFS(CLEANED_DATA!Q2:'CLEANED_DATA'!Q2080,CLEANED_DATA!W2:'CLEANED_DATA'!W2080,A20) -> 49047917 | D20: =IF(B20=0,0,SUMIFS(CLEANED_DATA!V2:'CLEANED_DATA'!V2080,CLEANED_DATA!W2:'CLEANED_DATA'!W2080,A20)/B20) -> 2.241756e-06 | E20: =C20+0 -> 49047917
A21: 8001-2STEEL | B21: =SUMIFS(CLEANED_DATA!U2:'CLEANED_DATA'!U2080,CLEANED_DATA!W2:'CLEANED_DATA'!W2080,A21) -> 164400 | C21: =SUMIFS(CLEANED_DATA!Q2:'CLEANED_DATA'!Q2080,CLEANED_DATA!W2:'CLEANED_DATA'!W2080,A21) -> 2326348.4 | D21: =IF(B21=0,0,SUMIFS(CLEANED_DATA!V2:'CLEANED_DATA'!V2080,CLEANED_DATA!W2:'CLEANED_DATA'!W2080,A21)/B21) -> 1.0218978e-06 | E21: =C21+0 -> 2326348.4
A22: 8504 | B22: =SUMIFS(CLEANED_DATA!U2:'CLEANED_DATA'!U2080,CLEANED_DATA!W2:'CLEANED_DATA'!W2080,A22) -> 176640 | C22: =SUMIFS(CLEANED_DATA!Q2:'CLEANED_DATA'!Q2080,CLEANED_DATA!W2:'CLEANED_DATA'!W2080,A22) -> 40185354 | D22: =IF(B22=0,0,SUMIFS(CLEANED_DATA!V2:'CLEANED_DATA'!V2080,CLEANED_DATA!W2:'CLEANED_DATA'!W2080,A22)/B22) -> 0.00010586504 | E22: =C22+0 -> 40185354
A23: 8505 | B23: =SUMIFS(CLEANED_DATA!U2:'CLEANED_DATA'!U2080,CLEANED_DATA!W2:'CLEANED_DATA'!W2080,A23) -> 67200 | C23: =SUMIFS(CLEANED_DATA!Q2:'CLEANED_DATA'!Q2080,CLEANED_DATA!W2:'CLEANED_DATA'!W2080,A23) -> 25372070 | D23: =IF(B23=0,0,SUMIFS(CLEANED_DATA!V2:'CLEANED_DATA'!V2080,CLEANED_DATA!W2:'CLEANED_DATA'!W2080,A23)/B23) -> 0.00021875 | E23: =C23+0 -> 25372070
A24: AISI430 | B24: =SUMIFS(CLEANED_DATA!U2:'CLEANED_DATA'!U2080,CLEANED_DATA!W2:'CLEANED_DATA'!W2080,A24) -> 2 | C24: =SUMIFS(CLEANED_DATA!Q2:'CLEANED_DATA'!Q2080,CLEANED_DATA!W2:'CLEANED_DATA'!W2080,A24) -> 1052919.6 | D24: =IF(B24=0,0,SUMIFS(CLEANED_DATA!V2:'CLEANED_DATA'!V2080,CLEANED_DATA!W2:'CLEANED_DATA'!W2080,A24)/B24) -> 0 | E24: =C24+0 -> 1052919.6
A25: AM-06 | B25: =SUMIFS(CLEANED_DATA!U2:'CLEANED_DATA'!U2080,CLEANED_DATA!W2:'CLEANED_DATA'!W2080,A25) -> 454944 | C25: =SUMIFS(CLEANED_DATA!Q2:'CLEANED_DATA'!Q2080,CLEANED_DATA!W2:'CLEANED_DATA'!W2080,A25) -> 42338893 | D25: =IF(B25=0,0,SUMIFS(CLEANED_DATA!V2:'CLEANED_DATA'!V2080,CLEANED_DATA!W2:'CLEANED_DATA'!W2080,A25)/B25) -> 4.9581927e-05 | E25: =C25+0 -> 42338893
A26: AM-06-STAINLESS | B26: =SUMIFS(CLEANED_DATA!U2:'CLEANED_DATA'!U2080,CLEANED_DATA!W2:'CLEANED_DATA'!W2080,A26) -> 9792 | C26: =SUMIFS(CLEANED_DATA!Q2:'CLEANED_DATA'!Q2080,CLEANED_DATA!W2:'CLEANED_DATA'!W2080,A26) -> 962858.84 | D26: =IF(B26=0,0,SUMIFS(CLEANED_DATA!V2:'CLEANED_DATA'!V2080,CLEANED_DATA!W2:'CLEANED_DATA'!W2080,A26)/B26) -> 0.00011642157 | E26: =C26+0 -> 962858.84
